Workbook

Sheet Info
B2: GoService — Test Scenario (QA Manual / Black-Box)
B3: Pengujian manual pada aplikasi terpasang (Android & iOS) — tanpa akses kode, murni dari sisi pengguna.
B6: Versi Dokumen | C6: 2.1 (black-box)
B7: Tanggal Dibuat | C7: 2026-06-02
B8: Jenis Pengujian | C8: Manual, black-box. Tester hanya memakai aplikasi terpasang (APK/IPA).
B9: Cakupan | C9: Onboarding, Profil, Kendaraan, Servis (Komponen/Rutin/Manual), Komponen, Pengingat (Komponen/Manual), Backup/Restore, Pengaturan (toggle + tes notif), Notifikasi (Pengingat servis & Update KM), Non-Fungsional
B10: Locale / Mata Uang / Jarak | C10: id-ID / IDR (Rp) / km
B11: Perangkat Uji | C11: Catat: merek/model, versi OS (Android/iOS), ukuran layar.
B13: ASUMSI BLACK-BOX (penting)
B14: • | C14: Tester TIDAK melihat kode, database, maupun log internal.
B15: • | C15: Tester TIDAK bisa memalsukan kegagalan internal (mis. error simpan database).
B16: • | C16: Verifikasi hanya dari yang TAMPIL di layar: teks, tombol, pesan, daftar, badge, notifikasi.
B17: • | C17: Kondisi error yang diuji hanya yang bisa direproduksi pengguna: input salah, izin ditolak, file salah, koneksi/penyimpanan, tutup-buka aplikasi.
B19: CARA PAKAI
B20: 1. | C20: Tiap modul punya sheet sendiri (lihat tab). Filter aktif di baris header.
B21: 2. | C21: Isi 'Hasil Aktual', 'Status' (dropdown), dan 'Catatan' saat eksekusi.
B22: 3. | C22: Status: Belum Diuji / Pass / Fail / Blocked / N/A.
B23: 4. | C23: Bug ditulis di Catatan + lampirkan langkah reproduksi & screenshot di tracker.
B25: LEGENDA TIPE
B26: Positif | C26: Alur normal dengan input benar.
B27: Negatif | C27: Input salah / kondisi yang harus ditolak — yang bisa direproduksi pengguna.
B28: Boundary | C28: Nilai batas (min/maks tahun, 0, batas karakter, dsb).
B29: UI/UX | C29: Tampilan, state kosong, loading, navigasi, format angka/tanggal.
B30: Fungsional | C30: Perilaku lintas-layar yang teramati (odometer ikut terbarui, jadwal komponen, dll).
B32: LEGENDA PRIORITAS
B33: Tinggi | C33: Fungsi inti / blocker rilis.
B34: Sedang | C34: Penting, ada workaround.
B35: Rendah | C35: Kosmetik / edge case jarang.
B37: ATURAN PRODUK YANG TERLIHAT PENGGUNA (acuan verifikasi)
B38: Kendaraan | C38: Nama panggilan & merek wajib. Tahun boleh kosong; jika diisi harus 1950–2100. Odometer tidak boleh minus.
B39: Odometer | C39: Tidak bisa diubah ke nilai lebih kecil dari saat ini kecuali pengguna mengonfirmasi koreksi.
B40: Servis | C40: Servis: pilih mode Komponen / Rutin / Manual. Komponen wajib pilih dari komponen kendaraan yang dipantau. Rutin otomatis membuat pengingat berikutnya. Manual butuh judul bebas dan TIDAK membuat pengingat. Kendaraan, tanggal, dan odometer wajib. Jika odometer servis lebih besar, odometer kendaraan ikut naik.
B41: Pengingat | C41: Pengingat: pilih mode Komponen (auto isi judul, target km, dan tanggal dari interval komponen) atau Manual (judul bebas + pilih pemicu KM/Tanggal/Keduanya). Kendaraan wajib.
B42: Komponen | C42: Saat dilacak, aplikasi menghitung & menampilkan jadwal servis berikutnya. Badge urgensi: Aman / Segera / Terlewat.
B43: Profil | C43: Nama wajib, maksimal 20 karakter. Email opsional tapi jika diisi harus format email valid.
B44: Backup | C44: Hanya file backup GoService yang bisa diimpor. Impor ulang tidak menggandakan data yang sudah ada.
B46: DI LUAR CAKUPAN MANUAL QA (butuh tim dev / pengujian otomatis)
B47: • | C47: Memicu kegagalan internal database/penyimpanan secara sengaja.
B48: • | C48: Verifikasi nilai mentah di DB atau perhitungan milidetik tanggal.
B49: • | C49: Race-condition tingkat thread (selain uji tap-ganda yang terlihat di UI).
...

Sheet Onboarding
A1: ID | B1: Fitur / Sub-Fitur | C1: Judul Skenario | D1: Tipe | E1: Prioritas | F1: Prasyarat | G1: Langkah Pengujian | H1: Data Uji | I1: Hasil yang Diharapkan | J1: Hasil Aktual | K1: Status | L1: Catatan
A2: ONB-001 | B2: Layar Awal | C2: Onboarding muncul saat aplikasi baru dipasang | D2: Positif | E2: Tinggi | F2: Aplikasi baru di-install, belum pernah dipakai. | G2: 1. Buka aplikasi pertama kali. 2. Amati layar pertama. | H2: Fresh install. | I2: Muncul layar sambutan (onboarding), bukan langsung ke halaman utama. | K2: Belum Diuji
A3: ONB-002 | B3: Layar Awal | C3: Pengguna lama langsung ke halaman utama | D3: Positif | E3: Tinggi | F3: Onboarding sudah pernah diselesaikan sebelumnya. | G3: 1. Tutup lalu buka kembali aplikasi. | H3: — | I3: Langsung masuk halaman utama; onboarding tidak muncul lagi. | K3: Belum Diuji
A4: ONB-003 | B4: Welcome Carousel | C4: Geser & selesaikan layar sambutan | D4: UI/UX | E4: Sedang | F4: Di layar sambutan (beberapa halaman geser). | G4: 1. Geser tiap halaman. 2. Tekan Mulai/Lanjut. | H4: — | I4: Bisa berpindah antar halaman; tombol lanjut membawa ke pengisian nama. | K4: Belum Diuji
A5: ONB-004 | B5: Isi Nama | C5: Nama wajib diisi | D5: Negatif | E5: Tinggi | F5: Di langkah isi nama. | G5: 1. Biarkan nama kosong. 2. Tekan Lanjut. | H5: Nama kosong / hanya spasi. | I5: Tidak bisa lanjut; muncul pesan bahwa nama wajib diisi. | K5: Belum Diuji
A6: ONB-005 | B6: Isi Nama | C6: Nama maksimal 20 karakter | D6: Boundary | E6: Sedang | F6: Di langkah isi nama. | G6: 1. Ketik nama lebih dari 20 karakter. | H6: 30 karakter | I6: Hanya 20 karakter pertama yang masuk; sisanya tidak terketik. | K6: Belum Diuji
A7: ONB-006 | B7: Isi Nama | C7: Pesan error hilang setelah diperbaiki | D7: UI/UX | E7: Rendah | F7: Pesan 'nama wajib' sedang tampil. | G7: 1. Ketik nama yang benar. | H7: Nama = 'Azri' | I7: Pesan error hilang; tombol Lanjut aktif. | K7: Belum Diuji
A8: ONB-007 | B8: Isi Nama | C8: Lewati pengisian nama | D8: Fungsional | E8: Sedang | F8: Di langkah isi nama (jika tersedia opsi Lewati). | G8: 1. Tekan Lewati. | H8: — | I8: Lanjut ke langkah berikutnya tanpa wajib mengisi nama. | K8: Belum Diuji | L8: Cek apakah opsi Lewati tersedia.
A9: ONB-008 | B9: Pilih Tipe | C9: Pilih tipe kendaraan Motor / Mobil | D9: Positif | E9: Tinggi | F9: Di langkah pilih tipe. | G9: 1. Pilih Motor atau Mobil. 2. Lanjut. | H9: Motor / Mobil | I9: Tipe terpilih ditandai; menjadi default saat menambah kendaraan. | K9: Belum Diuji
A10: ONB-009 | B10: Tambah Kendaraan | C10: Tambah kendaraan pertama | D10: Positif | E10: Tinggi | F10: Di langkah tambah kendaraan. | G10: 1. Isi nama panggilan & merek + data lain. 2. Simpan. | H10: Vario, Honda, 2021 | I10: Kendaraan tersimpan; lanjut ke langkah izin notifikasi. | K10: Belum Diuji
A11: ONB-010 | B11: Tambah Kendaraan | C11: Lewati tambah kendaraan | D11: Fungsional | E11: Sedang | F11: Di langkah tambah kendaraan. | G11: 1. Tekan Lewati. | H11: — | I11: Onboarding lanjut tanpa membuat kendaraan; halaman utama nanti tampil kosong. | K11: Belum Diuji
A12: ONB-011 | B12: Izin Notifikasi | C12: Izin notifikasi diberikan | D12: Positif | E12: Tinggi | F12: Di langkah izin notifikasi. | G12: 1. Tekan minta izin. 2. Pilih Izinkan di dialog OS. | H12: Izinkan | I12: Onboarding lanjut; notifikasi nantinya bisa muncul. | K12: Belum Diuji
A13: ONB-012 | B13: Izin Notifikasi | C13: Izin notifikasi ditolak tetap bisa lanjut | D13: Negatif | E13: Sedang | F13: Di langkah izin notifikasi. | G13: 1. Tekan minta izin. 2. Pilih Tolak di dialog OS. | H13: Tolak | I13: Aplikasi tidak crash; pengguna tetap bisa menyelesaikan onboarding. | K13: Belum Diuji
A14: ONB-013 | B14: Penyelesaian | C14: Selesai onboarding & tidak muncul lagi | D14: Positif | E14: Tinggi | F14: Di langkah terakhir. | G14: 1. Tekan Selesai. 2. Tutup & buka ulang aplikasi. | H14: — | I14: Masuk halaman utama; saat dibuka ulang langsung ke halaman utama. | K14: Belum Diuji
A15: ONB-014 | B15: Lewati Semua | C15: Lewati seluruh onboarding sekaligus | D15: Fungsional | E15: Sedang | F15: Di tengah onboarding (jika tersedia Lewati semua). | G15: 1. Tekan Lewati semua. | H15: — | I15: Langsung masuk halaman utama; onboarding tidak muncul lagi. | K15: Belum Diuji | L15: Cek ketersediaan opsi.
A16: ONB-015 | B16: Resume | C16: Lanjutkan onboarding setelah ditutup | D16: Fungsional | E16: Sedang | F16: Berhenti di tengah onboarding lalu aplikasi ditutup paksa. | G16: 1. Buka ulang aplikasi sebelum selesai. | H16: — | I16: Onboarding melanjutkan dari langkah terakhir, bukan dari awal. | K16: Belum Diuji
A17: ONB-016 | B17: Navigasi | C17: Tombol kembali antar langkah | D17: UI/UX | E17: Rendah | F17: Di langkah selain yang pertama. | G17: 1. Tekan kembali. | H17: — | I17: Kembali ke langkah sebelumnya; input yang sudah diisi tidak hilang. | K17: Belum Diuji

Sheet Profil
A1: ID | B1: Fitur / Sub-Fitur | C1: Judul Skenario | D1: Tipe | E1: Prioritas | F1: Prasyarat | G1: Langkah Pengujian | H1: Data Uji | I1: Hasil yang Diharapkan | J1: Hasil Aktual | K1: Status | L1: Catatan
A2: PRF-001 | B2: Lihat Profil | C2: Profil otomatis tersedia setelah onboarding | D2: Positif | E2: Tinggi | F2: Onboarding selesai. | G2: 1. Buka halaman Profil. | H2: — | I2: Profil tampil dengan nama dari onboarding dan warna avatar. | K2: Belum Diuji
A3: PRF-002 | B3: Lihat Profil | C3: Inisial avatar dari huruf pertama nama | D3: UI/UX | E3: Rendah | F3: Profil memiliki nama. | G3: 1. Amati avatar. | H3: nama='azri' | I3: Avatar menampilkan inisial 'A' (huruf besar). | K3: Belum Diuji
A4: PRF-003 | B4: Edit Profil | C4: Ubah nama profil | D4: Positif | E4: Sedang | F4: Di layar Edit Profil. | G4: 1. Ubah nama. 2. Simpan. | H4: nama='Budi' | I4: Nama baru tersimpan dan tampil di halaman Profil. | K4: Belum Diuji
A5: PRF-004 | B5: Edit Profil | C5: Ubah warna avatar | D5: Positif | E5: Rendah | F5: Di layar Edit Profil. | G5: 1. Pilih warna lain. 2. Simpan. | H5: warna baru | I5: Warna avatar berubah sesuai pilihan. | K5: Belum Diuji
A6: PRF-005 | B6: Edit Profil | C6: Nama wajib diisi | D6: Negatif | E6: Sedang | F6: Di layar Edit Profil. | G6: 1. Hapus seluruh nama. 2. Amati tombol Simpan. | H6: nama kosong | I6: Muncul tanda nama wajib; tombol Simpan nonaktif. | K6: Belum Diuji
A7: PRF-006 | B7: Edit Profil | C7: Nama maksimal 20 karakter | D7: Boundary | E7: Sedang | F7: Di layar Edit Profil. | G7: 1. Ketik nama lebih dari 20 karakter. | H7: 25 karakter | I7: Hanya 20 karakter pertama yang masuk. | K7: Belum Diuji
A8: PRF-007 | B8: Edit Profil | C8: Email tidak valid ditolak | D8: Negatif | E8: Sedang | F8: Di layar Edit Profil. | G8: 1. Isi email tanpa format benar. 2. Amati tombol Simpan. | H8: 'azri@', 'azri.com', 'a@b' | I8: Muncul tanda email tidak valid; tombol Simpan nonaktif. | K8: Belum Diuji
A9: PRF-008 | B9: Edit Profil | C9: Email valid diterima | D9: Positif | E9: Sedang | F9: Di layar Edit Profil. | G9: 1. Isi email yang benar. 2. Simpan. | H9: azri@mail.com | I9: Tidak ada tanda error; profil tersimpan dengan email. | K9: Belum Diuji
A10: PRF-009 | B10: Edit Profil | C10: Email boleh dikosongkan | D10: Boundary | E10: Rendah | F10: Di layar Edit Profil. | G10: 1. Kosongkan email. 2. Simpan. | H10: email kosong | I10: Profil tersimpan tanpa email; tidak ada error. | K10: Belum Diuji
A11: PRF-010 | B11: Edit Profil | C11: Reset ke nilai default | D11: Fungsional | E11: Rendah | F11: Di layar Edit Profil setelah ada perubahan (jika tersedia Reset). | G11: 1. Tekan Reset ke default. | H11: — | I11: Nama/warna kembali ke nilai default; tanda error hilang. | K11: Belum Diuji | L11: Cek ketersediaan tombol.
A12: PRF-011 | B12: Edit Profil | C12: Tap Simpan dua kali tidak menggandakan | D12: Negatif | E12: Rendah | F12: Di layar Edit Profil. | G12: 1. Tekan Simpan dua kali sangat cepat. | H12: — | I12: Hanya satu kali tersimpan; tidak ada perilaku ganda/aneh. | K12: Belum Diuji

Sheet Kendaraan
A1: ID | B1: Fitur / Sub-Fitur | C1: Judul Skenario | D1: Tipe | E1: Prioritas | F1: Prasyarat | G1: Langkah Pengujian | H1: Data Uji | I1: Hasil yang Diharapkan | J1: Hasil Aktual | K1: Status | L1: Catatan
A2: VEH-001 | B2: Tambah Kendaraan | C2: Tambah kendaraan dengan data benar | D2: Positif | E2: Tinggi | F2: Berada di form Tambah Kendaraan. | G2: 1. Isi nama panggilan & merek + data lain. 2. Simpan. | H2: Vario, Honda, Vario 160, 2022, B1234XYZ, 1500 km | I2: Kendaraan tersimpan dan muncul di daftar. | K2: Belum Diuji
A3: VEH-002 | B3: Tambah Kendaraan | C3: Nama panggilan wajib | D3: Negatif | E3: Tinggi | F3: Di form Tambah Kendaraan. | G3: 1. Kosongkan nama panggilan. 2. Isi merek. 3. Coba simpan. | H3: nama kosong | I3: Tidak bisa tersimpan; ada penanda nama wajib / tombol simpan nonaktif. | K3: Belum Diuji
A4: VEH-003 | B4: Tambah Kendaraan | C4: Merek wajib | D4: Negatif | E4: Tinggi | F4: Di form Tambah Kendaraan. | G4: 1. Isi nama panggilan. 2. Kosongkan merek. 3. Coba simpan. | H4: merek kosong | I4: Tidak bisa tersimpan; ada penanda merek wajib. | K4: Belum Diuji
A5: VEH-004 | B5: Tambah Kendaraan | C5: Tahun boleh dikosongkan | D5: Boundary | E5: Sedang | F5: Di form Tambah Kendaraan. | G5: 1. Isi field wajib. 2. Biarkan tahun kosong. 3. Simpan. | H5: tahun kosong | I5: Kendaraan tetap tersimpan tanpa tahun. | K5: Belum Diuji
A6: VEH-005 | B6: Tambah Kendaraan | C6: Tahun di bawah 1950 ditolak | D6: Boundary | E6: Sedang | F6: Di form Tambah Kendaraan. | G6: 1. Isi tahun 1949. 2. Simpan. | H6: 1949 | I6: Ditolak; muncul pesan tahun di luar rentang yang diizinkan. | K6: Belum Diuji
A7: VEH-006 | B7: Tambah Kendaraan | C7: Tahun di atas 2100 ditolak | D7: Boundary | E7: Sedang | F7: Di form Tambah Kendaraan. | G7: 1. Isi tahun 2101. 2. Simpan. | H7: 2101 | I7: Ditolak; muncul pesan tahun di luar rentang. | K7: Belum Diuji
A8: VEH-007 | B8: Tambah Kendaraan | C8: Tahun batas 1950 & 2100 diterima | D8: Boundary | E8: Rendah | F8: Di form Tambah Kendaraan. | G8: 1. Uji tahun 1950, lalu 2100. | H8: 1950 / 2100 | I8: Keduanya tersimpan. | K8: Belum Diuji
A9: VEH-008 | B9: Tambah Kendaraan | C9: Judul daftar pakai nama panggilan / merek+model | D9: UI/UX | E9: Rendah | F9: Tambah kendaraan dengan & tanpa nama panggilan. | G9: 1. Amati judul di daftar. | H9: tanpa nama: Honda Beat | I9: Tanpa nama panggilan judul jadi 'merek model'; jika ada, pakai nama panggilan. | K9: Belum Diuji
A10: VEH-009 | B10: Edit Kendaraan | C10: Ubah data kendaraan | D10: Positif | E10: Tinggi | F10: Ada kendaraan. | G10: 1. Buka Edit. 2. Ubah model/plat. 3. Simpan. | H10: model='Vario 160 ABS' | I10: Perubahan tersimpan dan tampil di detail/daftar. | K10: Belum Diuji
A11: VEH-010 | B11: Hapus Kendaraan | C11: Hapus kendaraan | D11: Positif | E11: Tinggi | F11: Ada kendaraan, di layar Edit/Detail. | G11: 1. Tekan Hapus. 2. Konfirmasi. | H11: — | I11: Kendaraan hilang dari daftar. | K11: Belum Diuji | L11: Cek nasib servis/pengingat kendaraan tsb.
A12: VEH-011 | B12: Update Odometer | C12: Naikkan odometer | D12: Positif | E12: Tinggi | F12: Kendaraan odometer 1500 km. | G12: 1. Buka Update Odometer. 2. Isi nilai lebih besar. 3. Simpan. | H12: 1500 → 1800 | I12: Odometer kendaraan jadi 1800 km. | K12: Belum Diuji
A13: VEH-012 | B13: Update Odometer | C13: Tolak odometer mundur | D13: Negatif | E13: Tinggi | F13: Kendaraan odometer 1800 km. | G13: 1. Isi nilai lebih kecil. 2. Simpan. | H13: 1800 → 1500 | I13: Ditolak; muncul pesan odometer tidak boleh lebih kecil dari nilai sekarang. | K13: Belum Diuji
A14: VEH-013 | B14: Update Odometer | C14: Koreksi mundur saat dikonfirmasi | D14: Fungsional | E14: Sedang | F14: Kendaraan odometer 1800 km. | G14: 1. Isi nilai lebih kecil. 2. Konfirmasi koreksi (jika ada opsi). | H14: 1800 → 1500 | I14: Odometer berubah jadi 1500 setelah dikonfirmasi. | K14: Belum Diuji | L14: Cek apakah ada dialog konfirmasi.
A15: VEH-014 | B15: Update Odometer | C15: Nilai negatif tidak diterima | D15: Boundary | E15: Rendah | F15: Di Update Odometer. | G15: 1. Coba masukkan angka minus. | H15: -50 | I15: Tidak bisa menyimpan nilai negatif (minimal 0). | K15: Belum Diuji
A16: VEH-015 | B16: Daftar Kendaraan | C16: Urutan & pengurutan daftar | D16: UI/UX | E16: Rendah | F16: Beberapa kendaraan. | G16: 1. Buka daftar. 2. Coba opsi urut (jika ada). | H16: — | I16: Daftar tampil rapi; opsi urut (abjad/odometer/urgensi) bekerja sesuai pilihan. | K16: Belum Diuji
A17: VEH-016 | B17: Daftar Kendaraan | C17: Tampilan saat belum ada kendaraan | D17: UI/UX | E17: Sedang | F17: Tidak ada kendaraan. | G17: 1. Buka daftar. | H17: — | I17: Muncul tampilan kosong / ajakan menambah kendaraan, bukan layar blank atau crash. | K17: Belum Diuji
A18: VEH-017 | B18: Daftar Kendaraan | C18: Bottom-nav '+' saat garasi kosong → popup 'Tambah kendaraan dulu' | D18: UI/UX | E18: Tinggi | F18: Belum ada kendaraan. | G18: 1. Berada di Home empty state. 2. Tap tombol '+' di bottom nav. | H18: — | I18: Muncul popup 'Tambah kendaraan dulu' dengan tombol 'Tambah Kendaraan' (membuka form Tambah Kendaraan) dan 'Batal' (menutup popup). Tidak diarahkan ke Catat Servis. | K18: Belum Diuji
A19: VEH-018 | B19: Detail Kendaraan | C19: Kelola / Tambah Komponen dari Home tetap navigasi meski tanpa id eksplisit | D19: Fungsional | E19: Tinggi | F19: Ada minimal 1 kendaraan. | G19: 1. Dari Home, tap kartu kendaraan (atau row 'Lihat detail' di hero). 2. Tap 'Kelola' di bagian Komponen. 3. Kembali, lalu tap '+ Tambah komponen' di grid komponen. | H19: — | I19: Kedua aksi navigasi ke layar yang benar (Vehicle Components untuk Kelola, Add Custom Component untuk Tambah). Tidak ada tap yang diam tanpa reaksi. | K19: Belum Diuji
A20: VEH-019 | B20: Detail Kendaraan | C20: Bagian 'Servis terakhir' menampilkan data sebenarnya | D20: Fungsional | E20: Tinggi | F20: Sudah pernah catat minimal 1 servis untuk kendaraan ini. | G20: 1. Buka Detail Kendaraan. 2. Gulir ke bagian 'Servis terakhir'. | H20: — | I20: Daftar menampilkan hingga 3 servis terbaru kendaraan tersebut dengan tanggal id-ID, km berformat titik, biaya 'Rp ...'. Bila belum ada servis, tampil teks empty state mengarahkan ke tombol '+'. | K20: Belum Diuji

Sheet Servis
A1: ID | B1: Fitur / Sub-Fitur | C1: Judul Skenario | D1: Tipe | E1: Prioritas | F1: Prasyarat | G1: Langkah Pengujian | H1: Data Uji | I1: Hasil yang Diharapkan | J1: Hasil Aktual | K1: Status | L1: Catatan
A2: SVC-001 | B2: Catat Servis | C2: Catat servis dengan data benar | D2: Positif | E2: Tinggi | F2: Ada kendaraan terpilih. | G2: 1. Buka Catat Servis. 2. Pastikan mode 'Komponen' aktif. 3. Pilih kendaraan + 1 komponen yang dipantau. 4. Isi tanggal, odometer, biaya. 5. Simpan. | H2: mode=Komponen, kendaraan=Vario, komponen=Oli mesin, hari ini, 2000 km, Rp75.000 | I2: Servis tersimpan, muncul di Riwayat. Jadwal komponen oli mesin diperbarui (badge urgensi reset). | K2: Belum Diuji
A3: SVC-002 | B3: Catat Servis | C3: Kendaraan wajib dipilih | D3: Negatif | E3: Tinggi | F3: Tidak ada kendaraan (belum menambah kendaraan). | G3: 1. Buka Catat Servis. 2. Coba simpan. | H3: — | I3: Tidak bisa menyimpan tanpa kendaraan; tombol nonaktif / diarahkan menambah kendaraan. | K3: Belum Diuji
A4: SVC-003 | B4: Catat Servis | C4: Odometer wajib diisi | D4: Negatif | E4: Tinggi | F4: Di Catat Servis. | G4: 1. Kosongkan odometer. 2. Coba simpan. | H4: odometer kosong | I4: Tidak bisa menyimpan; tombol Simpan nonaktif sampai odometer diisi. | K4: Belum Diuji
A5: SVC-004 | B5: Catat Servis | C5: Biaya boleh 0 / kosong | D5: Boundary | E5: Sedang | F5: Di Catat Servis. | G5: 1. Biarkan biaya kosong/0. 2. Simpan. | H5: biaya 0 | I5: Tersimpan dengan biaya Rp0; tidak error. | K5: Belum Diuji
A6: SVC-005 | B6: Catat Servis | C6: Bengkel & catatan opsional | D6: Boundary | E6: Rendah | F6: Di Catat Servis. | G6: 1. Kosongkan bengkel & catatan. 2. Simpan. | H6: kosong | I6: Tersimpan; detail menampilkan bengkel/catatan kosong tanpa error. | K6: Belum Diuji
A7: SVC-006 | B7: Catat Servis | C7: Mode picker tampilkan Komponen / Rutin / Manual | D7: UI/UX | E7: Tinggi | F7: Di Catat Servis. | G7: 1. Buka Catat Servis. 2. Amati pilihan mode di bagian 'Jenis catatan'. | H7: — | I7: Terlihat 3 pilihan: Komponen (default), Rutin, Manual. Tap setiap mode mengubah konten form di bawahnya. | K7: Belum Diuji
A8: SVC-007 | B8: Catat Servis | C8: Mode Komponen ambil daftar dari komponen yang dipantau kendaraan terpilih | D8: Fungsional | E8: Sedang | F8: Kendaraan punya komponen yang dilacak. | G8: 1. Pilih kendaraan A (punya komponen dipantau X, Y). 2. Buka picker komponen — hanya X, Y yang tampil. 3. Ganti ke kendaraan B (punya P, Q) — picker berisi P, Q saja. | H8: — | I8: Picker komponen mengikuti kendaraan terpilih; tidak ada item global yang nyasar. | K8: Belum Diuji
A9: SVC-008 | B9: Catat Servis | C9: Odometer kendaraan ikut naik bila lebih tinggi | D9: Fungsional | E9: Tinggi | F9: Kendaraan odometer 2000 km. | G9: 1. Catat servis dengan odometer 2500. 2. Buka detail kendaraan. | H9: odometer servis 2500 | I9: Odometer kendaraan ikut menjadi 2500 km. | K9: Belum Diuji
A10: SVC-009 | B10: Catat Servis | C10: Odometer kendaraan tidak turun saat servis backdate | D10: Fungsional | E10: Tinggi | F10: Kendaraan odometer 2500 km. | G10: 1. Catat servis lama dengan odometer 2200. 2. Cek odometer kendaraan. | H10: odometer servis 2200 | I10: Odometer kendaraan tetap 2500 km (tidak ikut turun). | K10: Belum Diuji
A11: SVC-010 | B11: Catat Servis | C11: Servis dari pengingat menyelesaikan pengingat | D11: Fungsional | E11: Tinggi | F11: Buka Catat Servis lewat tombol pada sebuah pengingat. | G11: 1. Simpan servis. 2. Cek daftar/detail pengingat tsb. | H11: — | I11: Pengingat berubah status menjadi Selesai dan tertaut ke servis tersebut. | K11: Belum Diuji
A12: SVC-011 | B12: Catat Servis | C12: Servis komponen memperbarui jadwal berikutnya | D12: Fungsional | E12: Tinggi | F12: Buka Catat Servis dari komponen yang dilacak. | G12: 1. Simpan servis. 2. Cek detail komponen & pengingat. | H12: — | I12: Tanggal servis terakhir komponen terisi; jadwal servis berikutnya dihitung ulang; pengingat baru dibuat. | K12: Belum Diuji
A13: SVC-012 | B13: Edit Servis | C13: Form Edit memuat data lama | D13: UI/UX | E13: Sedang | F13: Ada catatan servis. | G13: 1. Buka Edit dari detail servis. | H13: — | I13: Semua field (jenis, tanggal, odometer, biaya, bengkel, catatan, komponen) sudah terisi sesuai data. | K13: Belum Diuji
... A29: SVC-028 | B29: Catat Servis | C29: Bottom-nav '+' saat kosong tampilkan popup, bukan masuk Catat Servis | D29: Negatif | E29: Tinggi | F29: Belum ada kendaraan sama sekali. | G29: 1. Pastikan Home menampilkan empty state. 2. Tap tombol '+' di bottom nav. | H29: — | I29: Muncul popup 'Tambah kendaraan dulu' dengan tombol 'Tambah Kendaraan'. Tidak masuk ke Catat Servis. Tap 'Tambah Kendaraan' membuka form Tambah Kendaraan. | K29: Belum Diuji

Sheet Komponen
A1: ID | B1: Fitur / Sub-Fitur | C1: Judul Skenario | D1: Tipe | E1: Prioritas | F1: Prasyarat | G1: Langkah Pengujian | H1: Data Uji | I1: Hasil yang Diharapkan | J1: Hasil Aktual | K1: Status | L1: Catatan
A2: CMP-001 | B2: Katalog Komponen | C2: Daftar komponen relevan tampil | D2: Positif | E2: Sedang | F2: Kendaraan terpilih. | G2: 1. Buka Tambah/Lacak Komponen. | H2: tipe Motor | I2: Daftar komponen yang sesuai tipe kendaraan tampil & terurut. | K2: Belum Diuji
A3: CMP-002 | B3: Katalog Komponen | C3: Pencarian komponen | D3: Fungsional | E3: Sedang | F3: Di daftar komponen. | G3: 1. Ketik kata kunci. | H3: 'oli' | I3: Daftar menyaring sesuai kata kunci. | K3: Belum Diuji
A4: CMP-003 | B4: Katalog Komponen | C4: Tambah komponen kustom | D4: Fungsional | E4: Sedang | F4: Di daftar komponen. | G4: 1. Ketik nama yang tidak ada di daftar. | H4: 'Filter Kabin XYZ' | I4: Muncul opsi menambahkan komponen kustom dengan nama tersebut. | K4: Belum Diuji
A5: CMP-004 | B5: Lacak Komponen | C5: Lacak komponen membuat jadwal & pengingat | D5: Fungsional | E5: Tinggi | F5: Kendaraan terpilih; komponen punya interval bawaan. | G5: 1. Lacak komponen. 2. Cek detail komponen & daftar pengingat. | H5: — | I5: Komponen tampil dengan jadwal servis berikutnya; sebuah pengingat otomatis dibuat. | K5: Belum Diuji
A6: CMP-005 | B6: Lacak Komponen | C6: Pilih interval bawaan atau kustom | D6: Fungsional | E6: Sedang | F6: Di layar lacak komponen. | G6: 1. Pilih interval bawaan. 2. Ganti ke kustom & isi nilai. | H6: bawaan / kustom | I6: Mode bawaan memakai interval default; mode kustom memunculkan input km/hari. | K6: Belum Diuji
A7: CMP-006 | B7: Lacak Komponen | C7: Komponen tanpa interval bawaan wajib isi kustom | D7: Boundary | E7: Sedang | F7: Komponen yang tidak punya interval bawaan. | G7: 1. Biarkan km & hari kosong. 2. Amati tombol Lacak. | H7: km & hari kosong | I7: Tombol Lacak nonaktif sampai km atau hari diisi. | K7: Belum Diuji
A8: CMP-007 | B8: Lacak Komponen | C8: Isi interval kustom km/hari | D8: Positif | E8: Sedang | F8: Mode kustom. | G8: 1. Isi km dan/atau hari. 2. Lacak. | H8: 3000 km / 180 hari | I8: Tersimpan; jadwal berikutnya mengikuti nilai kustom. | K8: Belum Diuji
A9: CMP-008 | B9: Lacak Komponen | C9: Buat komponen kustom lalu lacak | D9: Fungsional | E9: Sedang | F9: Nama tidak ada di daftar. | G9: 1. Tambah komponen kustom. 2. Isi interval. 3. Lacak. | H9: 'Filter Kabin XYZ' | I9: Komponen kustom dibuat dan langsung dilacak dengan jadwalnya. | K9: Belum Diuji
A10: CMP-009 | B10: Urgensi Komponen | C10: Badge Terlewat saat melewati jadwal | D10: Boundary | E10: Tinggi | F10: Komponen dengan jadwal yang sudah lewat (atur lewat tanggal/odometer servis lama). | G10: 1. Amati badge urgensi. | H10: jadwal sudah lewat | I10: Komponen ditandai 'Terlewat' (warna paling mendesak). | K10: Belum Diuji
A11: CMP-010 | B11: Urgensi Komponen | C11: Badge Segera saat mendekati jadwal | D11: Boundary | E11: Tinggi | F11: Komponen dengan jadwal sebentar lagi (mendekati km/tanggal). | G11: 1. Amati badge urgensi. | H11: mendekati jatuh tempo | I11: Komponen ditandai 'Segera'. | K11: Belum Diuji
A12: CMP-011 | B12: Urgensi Komponen | C12: Badge Aman saat masih jauh | D12: Boundary | E12: Sedang | F12: Komponen dengan jadwal masih lama. | G12: 1. Amati badge urgensi. | H12: jadwal masih jauh | I12: Komponen ditandai 'Aman'. | K12: Belum Diuji
A13: CMP-012 | B13: Detail Komponen | C13: Lihat detail komponen | D13: UI/UX | E13: Rendah | F13: Ada komponen yang dilacak. | G13: 1. Tap komponen. | H13: — | I13: Menampilkan nama, servis terakhir & berikutnya, interval, badge urgensi. | K13: Belum Diuji
... A16: CMP-015 | B16: Daftar Komponen | C16: Daftar komponen per kendaraan | D16: UI/UX | E16: Sedang | F16: Kendaraan punya beberapa komponen. | G16: 1. Buka komponen kendaraan. | H16: — | I16: Daftar komponen tampil lengkap dengan badge urgensi. | K16: Belum Diuji

Sheet Pengingat
A1: ID | B1: Fitur / Sub-Fitur | C1: Judul Skenario | D1: Tipe | E1: Prioritas | F1: Prasyarat | G1: Langkah Pengujian | H1: Data Uji | I1: Hasil yang Diharapkan | J1: Hasil Aktual | K1: Status | L1: Catatan
A2: RMD-001 | B2: Tambah Pengingat | C2: Manual: pengingat berbasis KM | D2: Positif | E2: Tinggi | F2: Ada kendaraan. | G2: 1. Pilih pemicu KM. 2. Isi target km. 3. Simpan. | H2: target 4000 km | I2: Pengingat tersimpan & tampil di daftar. | K2: Belum Diuji
A3: RMD-002 | B3: Tambah Pengingat | C3: Manual: pengingat berbasis Tanggal | D3: Positif | E3: Tinggi | F3: Ada kendaraan. | G3: 1. Pilih pemicu Tanggal. 2. Pilih tanggal. 3. Simpan. | H3: +30 hari | I3: Pengingat tersimpan. | K3: Belum Diuji
A4: RMD-003 | B4: Tambah Pengingat | C4: Manual: pengingat berbasis Keduanya | D4: Positif | E4: Sedang | F4: Ada kendaraan. | G4: 1. Pilih pemicu Keduanya. 2. Isi km & tanggal. 3. Simpan. | H4: 4000 km & +30 hari | I4: Pengingat tersimpan dengan dua pemicu. | K4: Belum Diuji
A5: RMD-004 | B5: Tambah Pengingat | C5: Judul wajib | D5: Negatif | E5: Tinggi | F5: Di Tambah Pengingat. | G5: 1. Kosongkan judul. 2. Coba simpan. | H5: judul kosong | I5: Tidak bisa simpan; tombol nonaktif / penanda judul wajib. | K5: Belum Diuji
A6: RMD-005 | B6: Tambah Pengingat | C6: Pemicu KM butuh nilai lebih dari 0 | D6: Boundary | E6: Sedang | F6: Pemicu KM. | G6: 1. Biarkan target km 0/kosong. 2. Coba simpan. | H6: 0 | I6: Tidak bisa simpan sampai target km diisi (> 0). | K6: Belum Diuji
A7: RMD-006 | B7: Tambah Pengingat | C7: Manual: target km terisi otomatis di atas odometer kendaraan terpilih | D7: UI/UX | E7: Rendah | F7: Kendaraan punya odometer. | G7: 1. Buka Tambah Pengingat (pemicu KM). | H7: odometer 2000 | I7: Target km sudah terisi otomatis dengan nilai lebih besar dari odometer saat ini. | K7: Belum Diuji
A8: RMD-007 | B8: Tambah Pengingat (Komponen) | C8: Mode Komponen otomatis isi judul + target km + tanggal dari interval komponen | D8: Positif | E8: Tinggi | F8: Kendaraan terpilih punya komponen dipantau dengan interval km+tanggal. | G8: 1. Buka Tambah Pengingat. 2. Mode Komponen. 3. Pilih kendaraan + 1 komponen (mis. Oli mesin). 4. Amati field Judul + Target KM + Tanggal. | H8: komponen Oli mesin interval 4.000 km / 6 bulan, odometer kendaraan 18.000 | I8: Judul otomatis 'Oli mesin'. Target KM otomatis = 18.000 + 4.000 = 22.000. Target Tanggal = hari ini + 6 bulan. Pemicu otomatis 'Keduanya'. Semua field masih bisa diubah pengguna. | K8: Belum Diuji
A9: RMD-008 | B9: Tambah Pengingat | C9: Manual: judul yang sudah diketik tidak ditimpa | D9: UI/UX | E9: Rendah | F9: Judul sudah diubah manual. | G9: 1. Edit judul. 2. Ganti jenis servis. | H9: judul='Servis besar' | I9: Judul tetap seperti yang diketik, tidak ditimpa otomatis. | K9: Belum Diuji
A10: RMD-009 | B10: Selesaikan Pengingat | C10: Tandai selesai | D10: Positif | E10: Tinggi | F10: Ada pengingat aktif. | G10: 1. Tekan Selesai. | H10: — | I10: Status pengingat menjadi Selesai; keluar dari daftar aktif. | K10: Belum Diuji
A11: RMD-010 | B11: Snooze Pengingat | C11: Tunda dengan berbagai durasi | D11: Positif | E11: Sedang | F11: Ada pengingat. | G11: 1. Pilih tunda 1 hari / 3 / 7 / 14 / 30. | H11: salah satu durasi | I11: Pengingat ditunda; tampil status tertunda hingga tanggal yang sesuai. | K11: Belum Diuji
A12: RMD-011 | B12: Abaikan Pengingat | C12: Abaikan pengingat | D12: Positif | E12: Sedang | F12: Ada pengingat. | G12: 1. Tekan Abaikan. | H12: — | I12: Pengingat tidak lagi muncul di daftar aktif. | K12: Belum Diuji
A13: RMD-012 | B13: Hapus Pengingat | C13: Hapus pengingat | D13: Positif | E13: Sedang | F13: Ada pengingat. | G13: 1. Hapus. 2. Konfirmasi. | H13: — | I13: Pengingat hilang dari daftar. | K13: Belum Diuji
... A18: RMD-017 | B18: Detail Pengingat | C18: Aksi dari layar detail | D18: Positif | E18: Sedang | F18: Di detail pengingat aktif. | G18: 1. Coba Selesai / Tunda / Abaikan / Hapus. | H18: — | I18: Tiap aksi mengubah status pengingat sesuai & tampilan ter-update. | K18: Belum Diuji
A19: RMD-018 | B19: Notifikasi | C19: Notifikasi muncul saat jatuh tempo | D19: Fungsional | E19: Tinggi | F19: Izin notifikasi diberikan & pengaturan notifikasi aktif. | G19: 1. Buat pengingat yang jatuh tempo (mis. tanggal sebelumnya / mendekati). 2. Tunggu jadwalnya. | H19: — | I19: Notifikasi pengingat muncul di perangkat pada waktunya. | K19: Belum Diuji | L19: Uji di Android & iOS.
A20: RMD-019 | B20: Notifikasi | C20: Tidak ada notifikasi saat dimatikan | D20: Negatif | E20: Sedang | F20: Pengaturan notifikasi pengingat = mati. | G20: 1. Buat pengingat jatuh tempo. 2. Tunggu jadwal. | H20: notifikasi mati | I20: Tidak ada notifikasi yang muncul. | K20: Belum Diuji
A21: RMD-020 | B21: Tambah Pengingat | C21: Mode picker tampilkan Komponen / Manual | D21: UI/UX | E21: Tinggi | F21: Di form Tambah Pengingat. | G21: 1. Amati pilihan mode 'Jenis pengingat'. | H21: — | I21: Terlihat 2 pilihan: Komponen (default) dan Manual. Tap mengubah isi form di bawahnya. | K21: Belum Diuji
A22: RMD-021 | B22: Tambah Pengingat (Komponen) | C22: Empty state saat kendaraan belum punya komponen dipantau | D22: Negatif | E22: Sedang | F22: Mode Komponen, kendaraan tanpa komponen dipantau. | G22: 1. Buka Tambah Pengingat. 2. Pilih kendaraan yang belum punya komponen. 3. Lihat area komponen. | H22: — | I22: Muncul info 'Belum ada komponen dipantau' yang mengarahkan ke Detail Kendaraan atau menyarankan mode Manual. Tombol Simpan tetap nonaktif. | K22: Belum Diuji
A23: RMD-022 | B23: Tambah Pengingat (Komponen) | C23: Buka via TrackedComponentDetail otomatis pilih komponen tersebut | D23: Fungsional | E23: Sedang | F23: Punya komponen dipantau. | G23: 1. Buka Detail Komponen X. 2. Tap 'Buat reminder dari komponen ini'. | H23: — | I23: Form Tambah Pengingat terbuka dalam mode Komponen dengan komponen X sudah terpilih dan field-field terisi otomatis. | K23: Belum Diuji
A24: RMD-023 | B24: Daftar Pengingat | C24: Label pemicu dalam bahasa Indonesia | D24: UI/UX | E24: Tinggi | F24: Ada minimal 3 pengingat: salah satu pemicu KM, satu Tanggal, satu Keduanya. | G24: 1. Buka daftar Pengingat. 2. Amati teks ringkasan pemicu setiap baris. | H24: — | I24: Tampilan id-ID dengan format: KM => 'Target 20.000 km' (separator titik). Tanggal => 'Jatuh tempo 5 Jun 2026'. Keduanya => 'Target 20.000 km · 5 Jun 2026'. Tidak ada teks Inggris seperti 'due date set'. | K24: Belum Diuji
A25: RMD-024 | B25: Notifikasi | C25: Tap notif Pengingat servis buka layar Detail Reminder | D25: Fungsional | E25: Tinggi | F25: Notifikasi Pengingat servis sudah aktif; ada 1 pengingat aktif yang sudah pernah memunculkan notif (atau gunakan tombol Tes notif servis di Pengaturan). | G25: 1. Tampilkan notif servis (atau tap 'Tes notif servis' di Pengaturan). 2. Tap pada notifikasi. | H25: — | I25: Aplikasi terbuka langsung ke halaman Detail Pengingat sesuai reminderId notifikasi (atau ke halaman default jika notifikasi tes tanpa id valid). | K25: Belum Diuji

Sheet Backup-Restore
A1: ID | B1: Fitur / Sub-Fitur | C1: Judul Skenario | D1: Tipe | E1: Prioritas | F1: Prasyarat | G1: Langkah Pengujian | H1: Data Uji | I1: Hasil yang Diharapkan | J1: Hasil Aktual | K1: Status | L1: Catatan
A2: BKP-001 | B2: Export | C2: Export semua data | D2: Positif | E2: Tinggi | F2: Ada data kendaraan/servis/pengingat/komponen. | G2: 1. Buka Backup. 2. Pilih semua bagian, periode Semua. 3. Export. | H2: semua bagian | I2: File backup terbuat; ringkasan jumlah per bagian cocok dengan data. | K2: Belum Diuji
A3: BKP-002 | B3: Export | C3: Nama file mengandung tanggal | D3: UI/UX | E3: Rendah | F3: Export berhasil. | G3: 1. Lihat nama file. | H3: — | I3: Nama file memuat tanggal (mis. servisgo-backup-2026-06-01.csv). | K3: Belum Diuji
A4: BKP-003 | B4: Export | C4: Periode membatasi data servis | D4: Fungsional | E4: Sedang | F4: Ada servis lama (lebih dari setahun) dan baru. | G4: 1. Export periode 1 bulan / 3 bulan / 1 tahun. | H4: pilih periode | I4: Hanya servis dalam periode yang ikut; data kendaraan/komponen tetap lengkap. | K4: Belum Diuji
A5: BKP-004 | B5: Export | C5: Pilih sebagian bagian saja | D5: Fungsional | E5: Sedang | F5: Ada semua jenis data. | G5: 1. Pilih hanya Kendaraan + Servis. 2. Export. | H5: 2 bagian | I5: Hanya bagian terpilih yang ikut; ringkasan bagian lain 0. | K5: Belum Diuji
A6: BKP-005 | B6: Export | C6: Bagikan file hasil export | D6: Fungsional | E6: Tinggi | F6: Export berhasil. | G6: 1. Tekan Bagikan. 2. Pilih tujuan (mis. email/Drive/Files). | H6: — | I6: Lembar berbagi OS muncul; file bisa dikirim ke aplikasi lain. | K6: Belum Diuji | L6: Android & iOS.
A7: BKP-006 | B7: Import | C7: Import file backup yang valid | D7: Positif | E7: Tinggi | F7: Punya file backup hasil export. | G7: 1. Buka Pengaturan > Import. 2. Pilih file backup. | H7: file valid | I7: Data masuk; muncul ringkasan jumlah yang diimpor. | K7: Belum Diuji
A8: BKP-007 | B8: Import | C8: Tolak file yang bukan backup GoService | D8: Negatif | E8: Tinggi | F8: Punya file teks/CSV sembarangan. | G8: 1. Import file tersebut. | H8: file acak | I8: Aplikasi menolak; muncul pesan file tidak dikenali; tidak ada data yang masuk. | K8: Belum Diuji
A9: BKP-008 | B9: Import | C9: Import ulang tidak menggandakan data | D9: Fungsional | E9: Tinggi | F9: Data sudah ada, lalu import file yang berisi data sama + sebagian baru. | G9: 1. Import. 2. Lihat ringkasan & data. | H9: sebagian sudah ada | I9: Hanya data baru yang ditambahkan; data lama tidak terduplikasi; ringkasan menampilkan jumlah dilewati. | K9: Belum Diuji
A10: BKP-009 | B10: Import | C10: Pindah perangkat (export lalu import) | D10: Fungsional | E10: Tinggi | F10: Export di perangkat A. | G10: 1. Import file yang sama di perangkat lain/kosong. | H10: — | I10: Semua data pulih utuh: odometer, biaya (Rp), pemicu pengingat, badge urgensi konsisten. | K10: Belum Diuji
A11: BKP-010 | B11: Import | C11: File backup yang sebagian rusak | D11: Boundary | E11: Sedang | F11: File backup GoService yang dimodifikasi/terpotong sebagian. | G11: 1. Import file tersebut. | H11: file rusak sebagian | I11: Baris yang rusak dilewati; data yang masih valid tetap masuk; aplikasi tidak crash. | K11: Belum Diuji | L11: Edit manual file untuk uji.
A12: BKP-011 | B12: Import | C12: Batalkan pemilihan file | D12: UI/UX | E12: Rendah | F12: Di Import. | G12: 1. Buka pemilih file. 2. Tekan Batal. | H12: — | I12: Kembali ke Pengaturan tanpa perubahan; tidak ada error. | K12: Belum Diuji

Sheet Pengaturan
A1: ID | B1: Fitur / Sub-Fitur | C1: Judul Skenario | D1: Tipe | E1: Prioritas | F1: Prasyarat | G1: Langkah Pengujian | H1: Data Uji | I1: Hasil yang Diharapkan | J1: Hasil Aktual | K1: Status | L1: Catatan
A2: SET-001 | B2: Pengaturan | C2: Aktif/nonaktifkan notifikasi pengingat | D2: Positif | E2: Tinggi | F2: Di Pengaturan. | G2: 1. Lihat nilai awal. 2. Matikan lalu nyalakan. | H2: — | I2: Default menyala; perubahan langsung berlaku & memengaruhi notifikasi. | K2: Belum Diuji
A3: SET-002 | B3: Pengaturan | C3: Pengaturan tetap setelah aplikasi ditutup | D3: Fungsional | E3: Sedang | F3: Notifikasi diubah ke mati. | G3: 1. Tutup & buka ulang aplikasi. | H3: — | I3: Pengaturan tetap mati. | K3: Belum Diuji
A4: SET-003 | B4: Pengaturan | C4: Akses Export & Import | D4: UI/UX | E4: Sedang | F4: Di Pengaturan. | G4: 1. Buka menu Backup. | H4: — | I4: Tersedia menu Export dan Import. | K4: Belum Diuji
A5: SET-004 | B5: Pengaturan | C5: Akses Profil | D5: UI/UX | E5: Rendah | F5: Di Pengaturan. | G5: 1. Buka Profil. | H5: — | I5: Halaman Profil/Edit Profil terbuka. | K5: Belum Diuji
A6: SET-005 | B6: Pengaturan | C6: Toggle 'Pengingat update KM' (default nyala) | D6: Positif | E6: Tinggi | F6: Di Pengaturan → bagian Notifikasi. | G6: 1. Lihat nilai awal toggle 'Pengingat update KM'. 2. Matikan lalu nyalakan kembali. 3. Tutup & buka aplikasi. | H6: — | I6: Toggle baru terlihat di bawah 'Pengingat servis'. Default nyala. Nilai persist setelah restart. | K6: Belum Diuji
A7: SET-006 | B7: Pengaturan | C7: Tes notif servis: izin diminta jika belum | D7: Positif | E7: Tinggi | F7: Izin notifikasi belum diberikan (Android 13+) / belum ditentukan (iOS). | G7: 1. Buka Pengaturan → tap 'Tes notif servis'. | H7: — | I7: Muncul prompt izin notifikasi sistem. Bila diberi, notif tes muncul ~1 detik kemudian dengan judul 'Tes pengingat servis'. | K7: Belum Diuji
A8: SET-007 | B8: Pengaturan | C8: Tes notif Update KM butuh setidaknya 1 kendaraan | D8: Negatif | E8: Sedang | F8: Belum ada kendaraan. | G8: 1. Tap 'Tes notif update KM' di Pengaturan. | H8: — | I8: Tidak ada notif yang dikirim; muncul pesan singkat 'Tambah kendaraan dulu' (Toast Android / serupa iOS). | K8: Belum Diuji
A9: SET-008 | B9: Pengaturan | C9: Tes notif Update KM tap → buka Update KM kendaraan | D9: Fungsional | E9: Tinggi | F9: Ada minimal 1 kendaraan. Izin notifikasi diberikan. | G9: 1. Tap 'Tes notif update KM' di Pengaturan. 2. Buka shade notifikasi. 3. Tap notifikasi. | H9: — | I9: Notif tampil di channel 'Update KM' (Android) / kategori ODOMETER_REMINDER (iOS). Tap notif membuka layar Update KM untuk kendaraan pertama. | K9: Belum Diuji
A10: SET-009 | B10: Pengaturan | C10: Izin notifikasi ditolak → diarahkan ke Setelan | D10: Negatif | E10: Tinggi | F10: Pengguna sebelumnya menolak izin notifikasi atau memilih 'Jangan tanyakan lagi'. | G10: 1. Tap salah satu tombol Tes notif. | H10: — | I10: Android: muncul Toast 'Izin notifikasi ditolak. Aktifkan di Setelan...'. iOS: muncul alert 'Izin notifikasi dimatikan' dengan tombol 'Buka Setelan' yang membuka Setelan iOS. Tidak ada notif yang dikirim. | K10: Belum Diuji
A11: SET-010 | B11: Pengaturan | C11: Dua channel terpisah di Setelan sistem | D11: UI/UX | E11: Sedang | F11: Salah satu notif tes pernah dikirim (Android) / kategori sudah terdaftar (iOS). | G11: 1. Buka Setelan sistem → Aplikasi → ServisGo → Notifikasi. | H11: — | I11: Terlihat 2 kategori/channel: 'Pengingat servis' dan 'Update KM'. Masing-masing bisa dimatikan tanpa mempengaruhi yang lain. | K11: Belum Diuji
A12: SET-011 | B12: Pengaturan | C12: Pengingat Update KM otomatis terjadwal setelah 14 hari | D12: Fungsional | E12: Sedang | F12: Toggle 'Pengingat update KM' nyala. Ada kendaraan yang baru saja diisi odometer-nya hari ini. | G12: 1. Catat update KM untuk kendaraan A hari ini. 2. (Observasi) tunggu 14 hari, atau gunakan time-shift perangkat untuk maju 14 hari ke jam 9 pagi. | H12: — | I12: Pada jam 9 pagi hari ke-14, notif 'Update KM <kendaraan A>' muncul. Sebelum itu tidak ada notif update KM untuk kendaraan A. | K12: Belum Diuji

Sheet Non-Fungsional
A1: ID | B1: Fitur / Sub-Fitur | C1: Judul Skenario | D1: Tipe | E1: Prioritas | F1: Prasyarat | G1: Langkah Pengujian | H1: Data Uji | I1: Hasil yang Diharapkan | J1: Hasil Aktual | K1: Status | L1: Catatan
A2: NFR-001 | B2: Format | C2: Biaya tampil format Rupiah | D2: UI/UX | E2: Tinggi | F2: Ada data biaya. | G2: 1. Amati biaya di servis & riwayat. | H2: biaya 75000 | I2: Tampil 'Rp75.000', bukan angka mentah. | K2: Belum Diuji
A3: NFR-002 | B3: Format | C3: Jarak tampil dalam km | D3: UI/UX | E3: Sedang | F3: Ada odometer. | G3: 1. Amati odometer & target. | H3: 2000 | I3: Tampil '2.000 km'. | K3: Belum Diuji
A4: NFR-003 | B4: Format | C4: Tanggal format Indonesia | D4: UI/UX | E4: Sedang | F4: Ada tanggal servis/pengingat. | G4: 1. Amati tanggal. | H4: — | I4: Tanggal tampil dalam format Indonesia yang konsisten di semua layar. | K4: Belum Diuji
A5: NFR-004 | B5: Persistensi | C5: Data bertahan setelah aplikasi ditutup | D5: Fungsional | E5: Tinggi | F5: Sudah ada data. | G5: 1. Tutup paksa aplikasi. 2. Buka kembali. | H5: — | I5: Semua data (kendaraan/servis/pengingat/komponen) tetap ada. | K5: Belum Diuji
A6: NFR-005 | B6: Lintas Platform | C6: Perilaku konsisten Android & iOS | D6: Fungsional | E6: Tinggi | F6: Aplikasi terpasang di kedua platform. | G6: 1. Jalankan skenario inti di Android & iOS. | H6: — | I6: Perilaku & hasil sama; beda hanya pada tampilan berbagi/pemilih file bawaan OS. | K6: Belum Diuji
A7: NFR-006 | B7: Izin | C7: Notifikasi ditolak ditangani dengan baik | D7: Negatif | E7: Sedang | F7: Izin notifikasi ditolak di pengaturan OS. | G7: 1. Buat pengingat. | H7: — | I7: Aplikasi tidak crash; ada info bahwa izin diperlukan; fitur lain tetap jalan. | K7: Belum Diuji
A8: NFR-007 | B8: Lifecycle | C8: State form bertahan saat rotasi / pindah aplikasi | D8: UI/UX | E8: Rendah | F8: Sedang mengisi form (mis. Catat Servis). | G8: 1. Rotasi layar / pindah ke aplikasi lain lalu kembali. | H8: — | I8: Isian form tidak hilang. | K8: Belum Diuji
A9: NFR-008 | B9: Performa | C9: Riwayat dengan data banyak tetap lancar | D9: Fungsional | E9: Sedang | F9: Sangat banyak catatan servis. | G9: 1. Buka & scroll Riwayat. | H9: ratusan/ribuan catatan | I9: Scroll tetap mulus; tidak nge-freeze saat memuat. | K9: Belum Diuji
A10: NFR-009 | B10: Validasi | C10: Pesan error mudah dipahami | D10: UI/UX | E10: Sedang | F10: Memicu kesalahan input apa pun. | G10: 1. Lakukan aksi yang gagal validasi. | H10: — | I10: Muncul pesan jelas dalam bahasa Indonesia (mis. wajib diisi / di luar rentang), bukan teks teknis/crash. | K10: Belum Diuji
A11: NFR-010 | B11: Concurrency | C11: Tap tombol Simpan dua kali tidak menggandakan | D11: Negatif | E11: Sedang | F11: Di form Tambah/Edit apa pun. | G11: 1. Tekan Simpan dua kali sangat cepat. | H11: — | I11: Data hanya tersimpan satu kali; tidak ada entri ganda. | K11: Belum Diuji
A12: NFR-011 | B12: State | C12: Tombol Simpan nonaktif sebelum data lengkap | D12: UI/UX | E12: Sedang | F12: Di form Tambah/Edit apa pun. | G12: 1. Amati tombol Simpan sebelum & sesudah field wajib terisi. | H12: — | I12: Tombol Simpan nonaktif sampai semua syarat terpenuhi. | K12: Belum Diuji
A13: NFR-012 | B13: Empty State | C13: Tampilan kosong di tiap daftar | D13: UI/UX | E13: Rendah | F13: Belum ada data di kendaraan/servis/pengingat/komponen. | G13: 1. Buka tiap daftar. | H13: — | I13: Tiap daftar menampilkan pesan kosong / ajakan menambah, bukan layar blank. | K13: Belum Diuji

Sheet Ringkasan
B2: Ringkasan Eksekusi
B4: Modul | C4: Jumlah Test Case | D4: Pass | E4: Fail | F4: Blocked | G4: Belum Diuji
B5: Onboarding | C5: 16 | D5: =COUNTIF('Onboarding'!K2:K17,"Pass") | E5: =COUNTIF('Onboarding'!K2:K17,"Fail") | F5: =COUNTIF('Onboarding'!K2:K17,"Blocked") | G5: =COUNTIF('Onboarding'!K2:K17,"Belum Diuji")
B6: Profil | C6: 11 | D6: =COUNTIF('Profil'!K2:K12,"Pass") | E6: =COUNTIF('Profil'!K2:K12,"Fail") | F6: =COUNTIF('Profil'!K2:K12,"Blocked") | G6: =COUNTIF('Profil'!K2:K12,"Belum Diuji")
B7: Kendaraan | C7: 16 | D7: =COUNTIF('Kendaraan'!K2:K17,"Pass") | E7: =COUNTIF('Kendaraan'!K2:K17,"Fail") | F7: =COUNTIF('Kendaraan'!K2:K17,"Blocked") | G7: =COUNTIF('Kendaraan'!K2:K17,"Belum Diuji")
B8: Servis | C8: 21 | D8: =COUNTIF('Servis'!K2:K22,"Pass") | E8: =COUNTIF('Servis'!K2:K22,"Fail") | F8: =COUNTIF('Servis'!K2:K22,"Blocked") | G8: =COUNTIF('Servis'!K2:K22,"Belum Diuji")
B9: Komponen | C9: 15 | D9: =COUNTIF('Komponen'!K2:K16,"Pass") | E9: =COUNTIF('Komponen'!K2:K16,"Fail") | F9: =COUNTIF('Komponen'!K2:K16,"Blocked") | G9: =COUNTIF('Komponen'!K2:K16,"Belum Diuji")
B10: Pengingat | C10: 19 | D10: =COUNTIF('Pengingat'!K2:K20,"Pass") | E10: =COUNTIF('Pengingat'!K2:K20,"Fail") | F10: =COUNTIF('Pengingat'!K2:K20,"Blocked") | G10: =COUNTIF('Pengingat'!K2:K20,"Belum Diuji")
B11: Backup-Restore | C11: 11 | D11: =COUNTIF('Backup-Restore'!K2:K12,"Pass") | E11: =COUNTIF('Backup-Restore'!K2:K12,"Fail") | F11: =COUNTIF('Backup-Restore'!K2:K12,"Blocked") | G11: =COUNTIF('Backup-Restore'!K2:K12,"Belum Diuji")
B12: Pengaturan | C12: 4 | D12: =COUNTIF('Pengaturan'!K2:K5,"Pass") | E12: =COUNTIF('Pengaturan'!K2:K5,"Fail") | F12: =COUNTIF('Pengaturan'!K2:K5,"Blocked") | G12: =COUNTIF('Pengaturan'!K2:K5,"Belum Diuji")
B13: Non-Fungsional | C13: 12 | D13: =COUNTIF('Non-Fungsional'!K2:K13,"Pass") | E13: =COUNTIF('Non-Fungsional'!K2:K13,"Fail") | F13: =COUNTIF('Non-Fungsional'!K2:K13,"Blocked") | G13: =COUNTIF('Non-Fungsional'!K2:K13,"Belum Diuji")
B14: TOTAL | C14: 125 | D14: =SUM(D5:D13) | E14: =SUM(E5:E13) | F14: =SUM(F5:F13) | G14: =SUM(G5:G13)
